Workbook

Sheet Instruções
B2: FACSS — CRM Otimizado (Clientes + Pipeline)
B3: Reconstrução da sua aba Clientes: 1 linha por cliente, atributos em colunas com listas suspensas, log de meses normalizado.
B5: Abas
B6: Clientes | C6: Um cliente por linha. Colunas de Status, Faturamento, Acesso, Fidelidade, Módulos, Treinamento e Evolução têm listas suspensas (padroniza o preenchimento). A coluna 'Health' é automática.
B7: Interações | C7: Substitui as 12 colunas de meses. Cada contato = 1 linha (Data, Cliente, Responsável, Tipo, Observação, Próximo passo). Migrei jun/jul como exemplo. Continue registrando aqui.
B8: Pipeline | C8: Funil de NOVOS clientes (os 29 lookalikes de RLR/Aperam/Sempre Volta). Estágio com dropdown; 'Valor ponderado' calcula sozinho (veículos × ticket × probabilidade do estágio).
B9: Dashboard | C9: Tudo automático por fórmula: carteira por status, faturamento, health, veículos, carga por responsável e funil comercial.
B10: Config | C10: Listas das suspensas e o Ticket (R$/veículo/mês) em P2 — edite com seu valor real.
B11: Como importar no Google Sheets | C11: Abra sua planilha → Arquivo → Importar → Enviar (faça upload deste .xlsx) → escolha 'Inserir nova(s) aba(s)'. As 6 abas entram sem apagar o que você já tem.
B12: Preencher | C12: As colunas em amarelo (Config P2) e as datas/próximas ações são pra você manter. Use as suspensas — não digite texto livre nos campos de status.
B13: Exemplo de linha (Clientes) | C13: ÁGUA BONITA | Ativo | Faturando | Diego | ... | 6 veículos | Não faz | Telemetria II | Sem fidelidade | Módulos operando | Desatualizado | Sem evolução → Health = 🟡 Atenção (fatura, mas treinamento desatualizado).

Sheet Dicionário de Aprendizado
A1: 📘 Dicionário de Aprendizado — CRM FACSS
A2: Termo | B2: Significado / O que representa | C2: Observações
A3: ABAS DA PLANILHA
A4: Instruções | B4: Aba-guia com o passo a passo e a lógica de montagem do CRM. | C4: Leia antes de preencher.
A5: Dashboard | B5: Painel de indicadores calculado automaticamente por fórmulas. | C5: Não edite manualmente.
A6: Clientes | B6: Cadastro da carteira: 1 linha por cliente. | C6: A coluna Health é automática.
A7: Interações | B7: Registro (log) de contatos: 1 linha por contato. | C7: Substituiu as antigas colunas de meses.
A8: Pipeline | B8: Funil de NOVOS clientes (prospecção comercial). | C8: Valor ponderado é automático.
A9: Config | B9: Listas suspensas e parâmetros da planilha. | C9: Não apagar; edite só os valores.
A10: STATUS DO CLIENTE
A11: Ativo | B11: Cliente já operando com o produto. | C11: Status da carteira.
A12: Período de teste | B12: Cliente em avaliação ou trial. | C12: Status da carteira.
A13: Proposta comercial | B13: Proposta enviada; cliente em decisão. | C13: Status da carteira.
A14: Prospecção | B14: Ainda em abordagem inicial. | C14: Status da carteira.
A15: FATURAMENTO
A16: Faturando | B16: Cliente gerando receita ativa.
A17: Sem faturar | B17: Cliente sem cobrança no momento.
A18: Faturamento inativo | B18: Já faturou, mas está parado.
A19: NÍVEL DE ACESSO (TELEMETRIA)
A20: Telemetria II | B20: Acesso e integração mais completos aos dados de telemetria.
A21: Telemetria I | B21: Acesso básico à telemetria.
A22: Sem acesso | B22: Sem integração de telemetria.
A23: SAÚDE DA CARTEIRA (HEALTH automático)
A24: Saudável | B24: Cliente em boa situação (verde). | C24: Calculado pelo sistema.
A25: Atenção | B25: Exige acompanhamento (amarelo). | C25: Calculado pelo sistema.
A26: Risco | B26: Risco de perda ou churn (vermelho). | C26: Calculado pelo sistema.
A27: Prospecção | B27: Ainda não é cliente efetivo.
A28: Sem dados (preencher) | B28: Faltam informações para calcular a saúde.
A29: FIDELIDADE, TREINAMENTO E EVOLUÇÃO
A30: Fidelidade 12 meses | B30: Contrato com fidelidade de 12 meses.
A31: Sem fidelidade | B31: Sem cláusula de fidelidade.
A32: Fidelizar | B32: Meta de conquistar a fidelidade do cliente.
A33: Módulos operando | B33: Módulos do produto em uso.
A34: Checar módulos | B34: Verificar quais módulos estão ativos.
A35: Atualizado | B35: Treinamento do cliente em dia.
A36: Desatualizado | B36: Treinamento pendente ou vencido.
A37: Com evolução | B37: Cliente evoluindo no uso do produto.
A38: Sem evolução | B38: Cliente estagnado no uso.
A39: SISTEMAS DE TELEMETRIA (fornecedores)
A40: AIKO | B40: Plataforma de rastreamento e telemetria.
...

Sheet Dashboard
B2: FACSS — Painel de Clientes & Pipeline
B3: Atualiza automaticamente conforme você edita as abas Clientes e Pipeline
B5: Carteira por status | E5: Health da carteira | H5: Pipeline comercial (novos)
B7: Ativos | C7: =COUNTIF(Clientes!$B$2:$B$51,"Ativo") -> 16 | E7: 🟢 Saudável | F7: =COUNTIF(Clientes!$E$2:$E$47,E7) -> 6 | H7: Lead | I7: =COUNTIF(Pipeline!$H$2:$H$300,"Lead") -> 24
B8: Período de teste | C8: =COUNTIF(Clientes!$B$2:$B$51,"Período de teste") -> 5 | E8: 🟡 Atenção | F8: =COUNTIF(Clientes!$E$2:$E$47,E8) -> 17 | H8: Contato feito | I8: =COUNTIF(Pipeline!$H$2:$H$300,"Contato feito") -> 0
B9: Proposta comercial | C9: =COUNTIF(Clientes!$B$2:$B$51,"Proposta comercial") -> 3 | E9: 🔴 Risco | F9: =COUNTIF(Clientes!$E$2:$E$47,E9) -> 1 | H9: Diagnóstico agendado | I9: =COUNTIF(Pipeline!$H$2:$H$300,"Diagnóstico agendado") -> 0
B10: Prospecção | C10: =COUNTIF(Clientes!$B$2:$B$51,"Prospecção") -> 6 | E10: ⚪ Sem dados | F10: =COUNTIF(Clientes!$E$2:$E$47,E10) -> 22 | H10: Diagnóstico feito | I10: =COUNTIF(Pipeline!$H$2:$H$300,"Diagnóstico feito") -> 0
B11: Clientes Inativo | C11: =COUNTIF(Clientes!$B$2:$B$48,"Inativo") -> 3 | H11: Proposta enviada | I11: =COUNTIF(Pipeline!$H$2:$H$300,"Proposta enviada") -> 0
B12: POCs Sem Evolução | C12: =COUNTIF(Clientes!$B$2:$B$51,"POC Sem Evolução") -> 10 | H12: Negociação | I12: =COUNTIF(Pipeline!$H$2:$H$300,"Negociação") -> 0
B13: Prospecção sem Sucesso | C13: =COUNTIF(Clientes!$B$2:$B$51,"Prospecção sem Sucesso") -> 3 | H13: Fechado - Ganho | I13: =COUNTIF(Pipeline!$H$2:$H$300,"Fechado - Ganho") -> 0
B15: Faturamento | E15: Operação
B17: Faturando | C17: =COUNTIF(Clientes!$C$2:$C$48,"Faturando") -> 15 | E17: Total de veículos | F17: =SUM(Clientes!$K$2:$K$501) -> 2072 | H17: Valor ponderado (R$/mês) | I17: =SUM(Pipeline!$K$2:$K$300) -> 0
B18: Sem faturar | C18: =COUNTIF(Clientes!$C$2:$C$48,"Sem faturar") -> 0 | E18: Interações registradas | F18: =COUNTA('Interações'!$A$2:$A$204) -> 127 | H18: Prospects (total) | I18: =COUNTA(Pipeline!$B$2:$B$300) -> 24
E19: Clientes p/ Diego | F19: =COUNTIF(Clientes!$D$2:$D$51,"Diego") -> 22
E20: Clientes p/ Guilherme | F20: =COUNTIF(Clientes!$D$2:$D$51,"Guilherme") -> 22
E21: Clientes p/ Pablo | F21: =COUNTIF(Clientes!$D$2:$D$51,"Pablo") -> 1

Sheet Clientes
A1: Cliente | B1: Status | C1: Faturamento | D1: Resp. | E1: Health | F1: CNPJ | G1: Contato | H1: Telefone | I1: E-mail | J1: Início | L1: Módulos | M1: Sistema Jornada | N1: Nível de acesso | O1: Fidelidade | P1: Treinamento | Q1: Evolução | R1: Última interação
A2: AAS SOLUÇÕES | B2: POC Sem Evolução | C2: Faturamento inativo | D2: Diego | E2: =IF(OR($B2="POC Sem Evolução",$B2="Prospecção Sem Sucesso",$B2="Inativo",$B2="Prospecção"), "⚪ Sem dados",IF($C2="Faturando",IF($Q2="Com evolução","🟢 Saudável",IF($Q2="Sem evolução", "🟡 Atenção",IF(AND($P2="Capacitação Efetiva",$L2="Módulos operando"),"🟢 Saudável","🟡 Atenção"))), IF(AND($B2="Ativo",$C2="Faturamento inativo"),"🔴 Risco",IF($C2="","⚪ Sem dados","🟡 Atenção")))) -> ⚪ Sem dados | F2: 07.453115/0001-80 | G2: Luiz Fernando | H2: (31) 97202-5800 | I2: administrtivo@solucoesaas.com.br | J2: 46009 | K2: =COUNTIFS('Módulos'!$G$2:$G$2464,A2,'Módulos'!$I$2:$I$2464,"ATIVO") -> 1 | L2: Telemetria suspensa | M2: Sem dados | N2: Sem acesso | O2: Sem fidelidade | P2: Inativado | Q2: Inativado | R2: 46149
A3: ÁGUA BONITA | B3: Ativo | C3: Faturando | D3: Diego | E3: =IF(OR($B3="POC Sem Evolução",$B3="Prospecção Sem Sucesso",$B3="Inativo",$B3="Prospecção"), "⚪ Sem dados",IF($C3="Faturando",IF($Q3="Com evolução","🟢 Saudável",IF($Q3="Sem evolução", "🟡 Atenção",IF(AND($P3="Capacitação Efetiva",$L3="Módulos operando"),"🟢 Saudável","🟡 Atenção"))), IF(AND($B3="Ativo",$C3="Faturamento inativo"),"🔴 Risco",IF($C3="","⚪ Sem dados","🟡 Atenção")))) -> 🟡 Atenção | F3: 01.042.849/0001-90 | G3: Diego | H3: (31) 3147-0266 / 99619-5320 | I3: diegoapc@yahoo.com.br | J3: 45939 | K3: =COUNTIFS('Módulos'!$G$2:$G$2464,A3,'Módulos'!$I$2:$I$2464,"ATIVO") -> 6 | L3: Módulos operando | M3: Não faz | N3: Telemetria II | O3: Sem fidelidade | P3: Realizar Capacitação | Q3: Sem evolução | R3: 46209
A4: APERAM Carvão | B4: Ativo | C4: Faturando | D4: Guilherme | E4: =IF(OR($B4="POC Sem Evolução",$B4="Prospecção Sem Sucesso",$B4="Inativo",$B4="Prospecção"), "⚪ Sem dados",IF($C4="Faturando",IF($Q4="Com evolução","🟢 Saudável",IF($Q4="Sem evolução", "🟡 Atenção",IF(AND($P4="Capacitação Efetiva",$L4="Módulos operando"),"🟢 Saudável","🟡 Atenção"))), IF(AND($B4="Ativo",$C4="Faturamento inativo"),"🔴 Risco",IF($C4="","⚪ Sem dados","🟡 Atenção")))) -> 🟡 Atenção | F4: 18.238.980/0094-20 | G4: Ailton | H4: (33) 99849-3803 | I4: ailton.azevedo@aperam.com.br | J4: 45887 | K4: =COUNTIFS('Módulos'!$G$2:$G$2464,A4,'Módulos'!$I$2:$I$2464,"ATIVO") -> 118 | L4: Módulos operando | M4: AIKO | N4: Telemetria I | O4: Sem fidelidade | P4: Capacitação Efetiva | Q4: Sem evolução | R4: 46216
A5: APERAM Madeira | B5: Período de teste | C5: Faturamento inativo | D5: Pablo | E5: =IF(OR($B5="POC Sem Evolução",$B5="Prospecção Sem Sucesso",$B5="Inativo",$B5="Prospecção"), "⚪ Sem dados",IF($C5="Faturando",IF($Q5="Com evolução","🟢 Saudável",IF($Q5="Sem evolução", "🟡 Atenção",IF(AND($P5="Capacitação Efetiva",$L5="Módulos operando"),"🟢 Saudável","🟡 Atenção"))), IF(AND($B5="Ativo",$C5="Faturamento inativo"),"🔴 Risco",IF($C5="","⚪ Sem dados","🟡 Atenção")))) -> 🟡 Atenção | F5: - | G5: João / Adilson Alves (Supervisor) | H5: (33) 99915-4208 / (38) 9906-3301 | I5: adilsom.alvesfernandes@aperam.com | J5: 45887 | K5: =COUNTIFS('Módulos'!$G$2:$G$2464,A5,'Módulos'!$I$2:$I$2464,"ATIVO") -> 4 | L5: Módulos operando | M5: Sem dados | N5: Sem acesso | O5: Fidelizar | P5: Realizar Capacitação | Q5: Em POC | R5: 46216
A6: BEIRA RIO | B6: Ativo | C6: Faturando | D6: Diego | E6: =IF(OR($B6="POC Sem Evolução",$B6="Prospecção Sem Sucesso",$B6="Inativo",$B6="Prospecção"), "⚪ Sem dados",IF($C6="Faturando",IF($Q6="Com evolução","🟢 Saudável",IF($Q6="Sem evolução", "🟡 Atenção",IF(AND($P6="Capacitação Efetiva",$L6="Módulos operando"),"🟢 Saudável","🟡 Atenção"))), IF(AND($B6="Ativo",$C6="Faturamento inativo"),"🔴 Risco",IF($C6="","⚪ Sem dados","🟡 Atenção")))) -> 🟡 Atenção | F6: 16.883.860/0001-50 | G6: Breno / Arthur | H6: (38) 98402-3720 | I6: breno@grupobeirario.com.br / arthur@grupobeirario.com.br | J6: 46017 | K6: =COUNTIFS('Módulos'!$G$2:$G$2464,A6,'Módulos'!$I$2:$I$2464,"ATIVO") -> 29 | L6: Módulos operando | M6: Sascar | N6: Telemetria II | O6: Sem fidelidade | P6: Capacitação Efetiva | Q6: Sem evolução | R6: 46225
A7: BRITO SERVIÇO | B7: POC Sem Evolução | C7: Faturamento inativo | D7: Guilherme | E7: =IF(OR($B7="POC Sem Evolução",$B7="Prospecção Sem Sucesso",$B7="Inativo",$B7="Prospecção"), "⚪ Sem dados",IF($C7="Faturando",IF($Q7="Com evolução","🟢 Saudável",IF($Q7="Sem evolução", "🟡 Atenção",IF(AND($P7="Capacitação Efetiva",$L7="Módulos operando"),"🟢 Saudável","🟡 Atenção"))), IF(AND($B7="Ativo",$C7="Faturamento inativo"),"🔴 Risco",IF($C7="","⚪ Sem dados","🟡 Atenção")))) -> ⚪ Sem dados | G7: Eric Julian | H7: (31) 99228-1313 | I7: ericjulian@britoservicos.com.br | J7: 45915 | K7: =COUNTIFS('Módulos'!$G$2:$G$2464,A7,'Módulos'!$I$2:$I$2464,"ATIVO") -> 0 | L7: Telemetria suspensa | M7: Sem dados | N7: Sem acesso | O7: Sem fidelidade | P7: Inativado | Q7: Inativado | R7: 46170
A8: CONFINS | B8: Proposta comercial | C8: Faturamento inativo | D8: Guilherme | E8: =IF(OR($B8="POC Sem Evolução",$B8="Prospecção Sem Sucesso",$B8="Inativo",$B8="Prospecção"), "⚪ Sem dados",IF($C8="Faturando",IF($Q8="Com evolução","🟢 Saudável",IF($Q8="Sem evolução", "🟡 Atenção",IF(AND($P8="Capacitação Efetiva",$L8="Módulos operando"),"🟢 Saudável","🟡 Atenção"))), IF(AND($B8="Ativo",$C8="Faturamento inativo"),"🔴 Risco",IF($C8="","⚪ Sem dados","🟡 Atenção")))) -> 🟡 Atenção | F8: - | G8: - | H8: - | I8: - | K8: =COUNTIFS('Módulos'!$G$2:$G$2464,A8,'Módulos'!$I$2:$I$2464,"ATIVO") -> 4 | L8: Módulos operando | M8: Sem dados | N8: Sem acesso | O8: Fidelizar | P8: Realizar Capacitação | Q8: Em POC | R8: 46219
A9: COOPERAUTO | B9: Prospecção | C9: Faturamento inativo | D9: Guilherme | E9: =IF(OR($B9="POC Sem Evolução",$B9="Prospecção Sem Sucesso",$B9="Inativo",$B9="Prospecção"), "⚪ Sem dados",IF($C9="Faturando",IF($Q9="Com evolução","🟢 Saudável",IF($Q9="Sem evolução", "🟡 Atenção",IF(AND($P9="Capacitação Efetiva",$L9="Módulos operando"),"🟢 Saudável","🟡 Atenção"))), IF(AND($B9="Ativo",$C9="Faturamento inativo"),"🔴 Risco",IF($C9="","⚪ Sem dados","🟡 Atenção")))) -> ⚪ Sem dados | F9: - | G9: - | H9: - | I9: - | K9: =COUNTIFS('Módulos'!$G$2:$G$2464,A9,'Módulos'!$I$2:$I$2464,"ATIVO") -> 0 | L9: Checar módulos | M9: Sem dados | N9: Sem acesso | O9: Fidelizar | P9: Realizar Capacitação | Q9: Sem dados
A10: COOPERVALE | B10: Prospecção sem Sucesso | C10: Faturamento inativo | D10: Diego | E10: =IF(OR($B10="POC Sem Evolução",$B10="Prospecção Sem Sucesso",$B10="Inativo",$B10="Prospecção"), "⚪ Sem dados",IF($C10="Faturando",IF($Q10="Com evolução","🟢 Saudável",IF($Q10="Sem evolução", "🟡 Atenção",IF(AND($P10="Capacitação Efetiva",$L10="Módulos operando"),"🟢 Saudável","🟡 Atenção"))), IF(AND($B10="Ativo",$C10="Faturamento inativo"),"🔴 Risco",IF($C10="","⚪ Sem dados","🟡 Atenção")))) -> ⚪ Sem dados | F10: - | G10: - | H10: - | I10: - | K10: =COUNTIFS('Módulos'!$G$2:$G$2464,A10,'Módulos'!$I$2:$I$2464,"ATIVO") -> 0 | L10: Telemetria suspensa | M10: Sem dados | N10: Sem acesso | O10: Fidelizar | P10: Inativado | Q10: Inativado | R10: 46212
A11: DELLMAR | B11: Prospecção | C11: Faturamento inativo | D11: Diego | E11: =IF(OR($B11="POC Sem Evolução",$B11="Prospecção Sem Sucesso",$B11="Inativo",$B11="Prospecção"), "⚪ Sem dados",IF($C11="Faturando",IF($Q11="Com evolução","🟢 Saudável",IF($Q11="Sem evolução", "🟡 Atenção",IF(AND($P11="Capacitação Efetiva",$L11="Módulos operando"),"🟢 Saudável","🟡 Atenção"))), IF(AND($B11="Ativo",$C11="Faturamento inativo"),"🔴 Risco",IF($C11="","⚪ Sem dados","🟡 Atenção")))) -> ⚪ Sem dados | F11: 13.254.104/0001-74 | G11: Rogerio | H11: (11) 99007-8588 | I11: rogerio.souza@dellmar.com.br | K11: =COUNTIFS('Módulos'!$G$2:$G$2464,A11,'Módulos'!$I$2:$I$2464,"ATIVO") -> 0 | L11: Checar módulos | M11: Sem dados | N11: Sem acesso | O11: Fidelizar | P11: Realizar Capacitação | Q11: Sem dados
A12: DNA | B12: Ativo | C12: Faturando | D12: Diego | E12: =IF(OR($B12="POC Sem Evolução",$B12="Prospecção Sem Sucesso",$B12="Inativo",$B12="Prospecção"), "⚪ Sem dados",IF($C12="Faturando",IF($Q12="Com evolução","🟢 Saudável",IF($Q12="Sem evolução", "🟡 Atenção",IF(AND($P12="Capacitação Efetiva",$L12="Módulos operando"),"🟢 Saudável","🟡 Atenção"))), IF(AND($B12="Ativo",$C12="Faturamento inativo"),"🔴 Risco",IF($C12="","⚪ Sem dados","🟡 Atenção")))) -> 🟡 Atenção | F12: 21.479.020/0001-67 | G12: Deivison | H12: (31) 99731-9189 | I12: dna.deivson@gmail.com / dna.mariana93@gmail.com | J12: 45901 | K12: =COUNTIFS('Módulos'!$G$2:$G$2464,A12,'Módulos'!$I$2:$I$2464,"ATIVO") -> 11 | L12: Módulos operando | M12: Não faz | N12: Telemetria II | O12: Fidelidade 12 meses | P12: Capacitação Efetiva | Q12: Sem evolução | R12: 46204
A13: EMF LOGÍSTICA | B13: POC Sem Evolução | C13: Faturamento inativo | D13: Guilherme | E13: =IF(OR($B13="POC Sem Evolução",$B13="Prospecção Sem Sucesso",$B13="Inativo",$B13="Prospecção"), "⚪ Sem dados",IF($C13="Faturando",IF($Q13="Com evolução","🟢 Saudável",IF($Q13="Sem evolução", "🟡 Atenção",IF(AND($P13="Capacitação Efetiva",$L13="Módulos operando"),"🟢 Saudável","🟡 Atenção"))), IF(AND($B13="Ativo",$C13="Faturamento inativo"),"🔴 Risco",IF($C13="","⚪ Sem dados","🟡 Atenção")))) -> ⚪ Sem dados | F13: 05.151.226/0001-07 | G13: Rafael | H13: (31) 9377-1430 | I13: rafael.oliveira@emflogistica.com.br / pedro.estrugiaki@emflogistica.com.br | J13: 45936 | K13: =COUNTIFS('Módulos'!$G$2:$G$2464,A13,'Módulos'!$I$2:$I$2464,"ATIVO") -> 44 | L13: Módulos operando | M13: Trucks Control | N13: Telemetria II | O13: Fidelizar | P13: Inativado | Q13: Inativado | R13: 46219
A14: EXPRESSO TRANSPORTE | B14: Ativo | C14: Faturando | D14: Diego | E14: =IF(OR($B14="POC Sem Evolução",$B14="Prospecção Sem Sucesso",$B14="Inativo",$B14="Prospecção"), "⚪ Sem dados",IF($C14="Faturando",IF($Q14="Com evolução","🟢 Saudável",IF($Q14="Sem evolução", "🟡 Atenção",IF(AND($P14="Capacitação Efetiva",$L14="Módulos operando"),"🟢 Saudável","🟡 Atenção"))), IF(AND($B14="Ativo",$C14="Faturamento inativo"),"🔴 Risco",IF($C14="","⚪ Sem dados","🟡 Atenção")))) -> 🟡 Atenção | F14: 27.892.478/0001-20 | G14: Marcos Gabriel | H14: (31) 97135-8694 | I14: administrativo@expressotransporte.com | J14: 46024 | K14: =COUNTIFS('Módulos'!$G$2:$G$2464,A14,'Módulos'!$I$2:$I$2464,"ATIVO") -> 19 | L14: Módulos operando | M14: Link | N14: Telemetria II | O14: Sem fidelidade | P14: Capacitação em Desenvolvimento | Q14: Sem evolução | R14: 46227
A15: FASI | B15: Período de teste | C15: Faturamento inativo | D15: Diego | E15: =IF(OR($B15="POC Sem Evolução",$B15="Prospecção Sem Sucesso",$B15="Inativo",$B15="Prospecção"), "⚪ Sem dados",IF($C15="Faturando",IF($Q15="Com evolução","🟢 Saudável",IF($Q15="Sem evolução", "🟡 Atenção",IF(AND($P15="Capacitação Efetiva",$L15="Módulos operando"),"🟢 Saudável","🟡 Atenção"))), IF(AND($B15="Ativo",$C15="Faturamento inativo"),"🔴 Risco",IF($C15="","⚪ Sem dados","🟡 Atenção")))) -> 🟡 Atenção | F15: 03.886.930/0001-82 | G15: Fabiano / João | H15: (31) 99957-6831 / (31) 99305-0034 | I15: fabianoalex@fasitransportes.com.br | J15: 45979 | K15: =COUNTIFS('Módulos'!$G$2:$G$2464,A15,'Módulos'!$I$2:$I$2464,"ATIVO") -> 4 | L15: Módulos operando | M15: Sem dados | N15: Telemetria II | O15: Fidelizar | P15: Capacitação em Desenvolvimento | Q15: Em POC | R15: 46217
A16: GERDAU LENARGE | B16: Inativo | C16: Faturamento inativo | D16: Guilherme | E16: =IF(OR($B16="POC Sem Evolução",$B16="Prospecção Sem Sucesso",$B16="Inativo",$B16="Prospecção"), "⚪ Sem dados",IF($C16="Faturando",IF($Q16="Com evolução","🟢 Saudável",IF($Q16="Sem evolução", "🟡 Atenção",IF(AND($P16="Capacitação Efetiva",$L16="Módulos operando"),"🟢 Saudável","🟡 Atenção"))), IF(AND($B16="Ativo",$C16="Faturamento inativo"),"🔴 Risco",IF($C16="","⚪ Sem dados","🟡 Atenção")))) -> ⚪ Sem dados | F16: - | G16: - | H16: - | I16: - | K16: =COUNTIFS('Módulos'!$G$2:$G$2464,A16,'Módulos'!$I$2:$I$2464,"ATIVO") -> 33 | L16: Telemetria suspensa | M16: Sem dados | N16: Sem acesso | O16: Sem fidelidade | P16: Inativado | Q16: Inativado
A17: GFM | B17: Ativo | C17: Faturando | D17: Diego | E17: =IF(OR($B17="POC Sem Evolução",$B17="Prospecção Sem Sucesso",$B17="Inativo",$B17="Prospecção"), "⚪ Sem dados",IF($C17="Faturando",IF($Q17="Com evolução","🟢 Saudável",IF($Q17="Sem evolução", "🟡 Atenção",IF(AND($P17="Capacitação Efetiva",$L17="Módulos operando"),"🟢 Saudável","🟡 Atenção"))), IF(AND($B17="Ativo",$C17="Faturamento inativo"),"🔴 Risco",IF($C17="","⚪ Sem dados","🟡 Atenção")))) -> 🟢 Saudável | F17: - | G17: - | H17: - | I17: - | K17: =COUNTIFS('Módulos'!$G$2:$G$2464,A17,'Módulos'!$I$2:$I$2464,"ATIVO") -> 9 | L17: Módulos operando | M17: Sem dados | N17: Telemetria II | O17: Fidelidade 12 meses | P17: Capacitação Efetiva | Q17: Com evolução | R17: 46217
A18: GTS | B18: POC Sem Evolução | C18: Faturamento inativo | D18: Diego | E18: =IF(OR($B18="POC Sem Evolução",$B18="Prospecção Sem Sucesso",$B18="Inativo",$B18="Prospecção"), "⚪ Sem dados",IF($C18="Faturando",IF($Q18="Com evolução","🟢 Saudável",IF($Q18="Sem evolução", "🟡 Atenção",IF(AND($P18="Capacitação Efetiva",$L18="Módulos operando"),"🟢 Saudável","🟡 Atenção"))), IF(AND($B18="Ativo",$C18="Faturamento inativo"),"🔴 Risco",IF($C18="","⚪ Sem dados","🟡 Atenção")))) -> ⚪ Sem dados | F18: - | G18: Jânio | H18: (11) 94187-733 | I18: janio.alves@gtstransportes.com.br | J18: 45973 | K18: =COUNTIFS('Módulos'!$G$2:$G$2464,A18,'Módulos'!$I$2:$I$2464,"ATIVO") -> 0 | L18: Telemetria suspensa | M18: Sem dados | N18: Sem acesso | O18: Sem fidelidade | P18: Inativado | Q18: Inativado | R18: 46189
A19: HERTEX | B19: Período de teste | C19: Faturamento inativo | D19: Diego | E19: =IF(OR($B19="POC Sem Evolução",$B19="Prospecção Sem Sucesso",$B19="Inativo",$B19="Prospecção"), "⚪ Sem dados",IF($C19="Faturando",IF($Q19="Com evolução","🟢 Saudável",IF($Q19="Sem evolução", "🟡 Atenção",IF(AND($P19="Capacitação Efetiva",$L19="Módulos operando"),"🟢 Saudável","🟡 Atenção"))), IF(AND($B19="Ativo",$C19="Faturamento inativo"),"🔴 Risco",IF($C19="","⚪ Sem dados","🟡 Atenção")))) -> 🟡 Atenção | F19: 24.070.142/0001-93 | G19: Lau | H19: (31) 98437-3092 | I19: - | J19: 45798 | K19: =COUNTIFS('Módulos'!$G$2:$G$2464,A19,'Módulos'!$I$2:$I$2464,"ATIVO") -> 3 | L19: Módulos operando | M19: Fastmine | N19: Telemetria II | O19: Fidelizar | P19: Capacitação em Desenvolvimento | Q19: Em POC | R19: 46219
A20: JAF | B20: Ativo | C20: Faturando | D20: Diego | E20: =IF(OR($B20="POC Sem Evolução",$B20="Prospecção Sem Sucesso",$B20="Inativo",$B20="Prospecção"), "⚪ Sem dados",IF($C20="Faturando",IF($Q20="Com evolução","🟢 Saudável",IF($Q20="Sem evolução", "🟡 Atenção",IF(AND($P20="Capacitação Efetiva",$L20="Módulos operando"),"🟢 Saudável","🟡 Atenção"))), IF(AND($B20="Ativo",$C20="Faturamento inativo"),"🔴 Risco",IF($C20="","⚪ Sem dados","🟡 Atenção")))) -> 🟡 Atenção | F20: 09.185.563/0001-76 | G20: Maria Clara | H20: (31) 99959-3176 | I20: controle.diesel@jaftransporte.com.br | J20: 46087 | K20: =COUNTIFS('Módulos'!$G$2:$G$2464,A20,'Módulos'!$I$2:$I$2464,"ATIVO") -> 56 | L20: Módulos operando | M20: SAT | N20: Telemetria II | O20: Fidelidade 12 meses | P20: Capacitação em Desenvolvimento | Q20: Sem evolução | R20: 46225
A21: LENARGE | B21: Ativo | C21: Faturando | D21: Guilherme | E21: =IF(OR($B21="POC Sem Evolução",$B21="Prospecção Sem Sucesso",$B21="Inativo",$B21="Prospecção"), "⚪ Sem dados",IF($C21="Faturando",IF($Q21="Com evolução","🟢 Saudável",IF($Q21="Sem evolução", "🟡 Atenção",IF(AND($P21="Capacitação Efetiva",$L21="Módulos operando"),"🟢 Saudável","🟡 Atenção"))), IF(AND($B21="Ativo",$C21="Faturamento inativo"),"🔴 Risco",IF($C21="","⚪ Sem dados","🟡 Atenção")))) -> 🟢 Saudável | F21: 02.870.124/0001-53 | G21: Matheus | H21: (31) 99969-5289 | I21: matheus@lenarge.com.br | J21: 45566 | K21: =COUNTIFS('Módulos'!$G$2:$G$2464,A21,'Módulos'!$I$2:$I$2464,"ATIVO") -> 1346 | L21: Módulos operando | M21: Sascar | N21: Telemetria I | O21: Sem fidelidade | P21: Capacitação Efetiva | Q21: Com evolução
A22: M1 | B22: Ativo | C22: Faturando | D22: Diego | E22: =IF(OR($B22="POC Sem Evolução",$B22="Prospecção Sem Sucesso",$B22="Inativo",$B22="Prospecção"), "⚪ Sem dados",IF($C22="Faturando",IF($Q22="Com evolução","🟢 Saudável",IF($Q22="Sem evolução", "🟡 Atenção",IF(AND($P22="Capacitação Efetiva",$L22="Módulos operando"),"🟢 Saudável","🟡 Atenção"))), IF(AND($B22="Ativo",$C22="Faturamento inativo"),"🔴 Risco",IF($C22="","⚪ Sem dados","🟡 Atenção")))) -> 🟡 Atenção | F22: 41.568.245/0001-05 | G22: Matheus | H22: (31) 99969-5289 | I22: matheus@lenarge.com.br | J22: 45901 | K22: =COUNTIFS('Módulos'!$G$2:$G$2464,A22,'Módulos'!$I$2:$I$2464,"ATIVO") -> 6 | L22: Módulos operando | M22: Sem dados | N22: Telemetria II | O22: Fidelidade 12 meses | P22: Capacitação Efetiva | Q22: Sem evolução
A23: MAGNO | B23: Ativo | C23: Faturando | D23: Diego | E23: =IF(OR($B23="POC Sem Evolução",$B23="Prospecção Sem Sucesso",$B23="Inativo",$B23="Prospecção"), "⚪ Sem dados",IF($C23="Faturando",IF($Q23="Com evolução","🟢 Saudável",IF($Q23="Sem evolução", "🟡 Atenção",IF(AND($P23="Capacitação Efetiva",$L23="Módulos operando"),"🟢 Saudável","🟡 Atenção"))), IF(AND($B23="Ativo",$C23="Faturamento inativo"),"🔴 Risco",IF($C23="","⚪ Sem dados","🟡 Atenção")))) -> 🟢 Saudável | F23: 34.391.213/0001-03 | G23: Reinaldo | H23: (31) 98793-0832 | I23: magnotransportes777@gmail.com | J23: 45901 | K23: =COUNTIFS('Módulos'!$G$2:$G$2464,A23,'Módulos'!$I$2:$I$2464,"ATIVO") -> 7 | L23: Módulos operando | M23: Sem dados | N23: Telemetria II | O23: Sem fidelidade | P23: Capacitação Efetiva | Q23: Com evolução
A24: MALIBU | B24: Prospecção | C24: Faturamento inativo | D24: Diego | E24: =IF(OR($B24="POC Sem Evolução",$B24="Prospecção Sem Sucesso",$B24="Inativo",$B24="Prospecção"), "⚪ Sem dados",IF($C24="Faturando",IF($Q24="Com evolução","🟢 Saudável",IF($Q24="Sem evolução", "🟡 Atenção",IF(AND($P24="Capacitação Efetiva",$L24="Módulos operando"),"🟢 Saudável","🟡 Atenção"))), IF(AND($B24="Ativo",$C24="Faturamento inativo"),"🔴 Risco",IF($C24="","⚪ Sem dados","🟡 Atenção")))) -> ⚪ Sem dados | F24: 97.442.123/0001-14 | G24: Fernando | H24: - | I24: fernando.miranda@malibutransportes.com.br | K24: =COUNTIFS('Módulos'!$G$2:$G$2464,A24,'Módulos'!$I$2:$I$2464,"ATIVO") -> 0 | L24: Checar módulos | M24: Sem dados | N24: Sem acesso | O24: Fidelizar | P24: Realizar Capacitação | Q24: Sem dados
A25: M&J | B25: Ativo | C25: Faturando | D25: Diego | E25: =IF(OR($B25="POC Sem Evolução",$B25="Prospecção Sem Sucesso",$B25="Inativo",$B25="Prospecção"), "⚪ Sem dados",IF($C25="Faturando",IF($Q25="Com evolução","🟢 Saudável",IF($Q25="Sem evolução", "🟡 Atenção",IF(AND($P25="Capacitação Efetiva",$L25="Módulos operando"),"🟢 Saudável","🟡 Atenção"))), IF(AND($B25="Ativo",$C25="Faturamento inativo"),"🔴 Risco",IF($C25="","⚪ Sem dados","🟡 Atenção")))) -> 🟡 Atenção | F25: 55.725.850/0001-49 | G25: Nayara | H25: (31) 97500-6409 | I25: nayara.moraes@lenarge.com.br | J25: 45952 | K25: =COUNTIFS('Módulos'!$G$2:$G$2464,A25,'Módulos'!$I$2:$I$2464,"ATIVO") -> 0 | L25: Módulos operando | M25: Sem dados | N25: Sem acesso | O25: Fidelidade 12 meses | P25: Capacitação Efetiva | Q25: Sem evolução
A26: MRX | B26: POC Sem Evolução | C26: Faturamento inativo | D26: Guilherme | E26: =IF(OR($B26="POC Sem Evolução",$B26="Prospecção Sem Sucesso",$B26="Inativo",$B26="Prospecção"), "⚪ Sem dados",IF($C26="Faturando",IF($Q26="Com evolução","🟢 Saudável",IF($Q26="Sem evolução", "🟡 Atenção",IF(AND($P26="Capacitação Efetiva",$L26="Módulos operando"),"🟢 Saudável","🟡 Atenção"))), IF(AND($B26="Ativo",$C26="Faturamento inativo"),"🔴 Risco",IF($C26="","⚪ Sem dados","🟡 Atenção")))) -> ⚪ Sem dados | F26: 26.586.645/001-41 | G26: Paulo Sérgio | H26: (31) 99670-0159 | I26: paulo.sergio@mrxtransportes.com | J26: 46037 | K26: =COUNTIFS('Módulos'!$G$2:$G$2464,A26,'Módulos'!$I$2:$I$2464,"ATIVO") -> 1 | L26: Telemetria suspensa | M26: Sem dados | N26: Sem acesso | O26: Sem fidelidade | P26: Inativado | Q26: Inativado | R26: 46158
A27: NOVA MINERAIS | B27: Ativo | C27: Faturamento inativo | D27: Guilherme | E27: =IF(OR($B27="POC Sem Evolução",$B27="Prospecção Sem Sucesso",$B27="Inativo",$B27="Prospecção"), "⚪ Sem dados",IF($C27="Faturando",IF($Q27="Com evolução","🟢 Saudável",IF($Q27="Sem evolução", "🟡 Atenção",IF(AND($P27="Capacitação Efetiva",$L27="Módulos operando"),"🟢 Saudável","🟡 Atenção"))), IF(AND($B27="Ativo",$C27="Faturamento inativo"),"🔴 Risco",IF($C27="","⚪ Sem dados","🟡 Atenção")))) -> 🔴 Risco | K27: =COUNTIFS('Módulos'!$G$2:$G$2464,A27,'Módulos'!$I$2:$I$2464,"ATIVO") -> 0 | L27: Módulos operando | M27: Sem dados | N27: Sem acesso | O27: Fidelizar | P27: Capacitação Efetiva | Q27: Sem dados
A28: P&W | B28: Proposta comercial | C28: Faturamento inativo | D28: Guilherme | E28: =IF(OR($B28="POC Sem Evolução",$B28="Prospecção Sem Sucesso",$B28="Inativo",$B28="Prospecção"), "⚪ Sem dados",IF($C28="Faturando",IF($Q28="Com evolução","🟢 Saudável",IF($Q28="Sem evolução", "🟡 Atenção",IF(AND($P28="Capacitação Efetiva",$L28="Módulos operando"),"🟢 Saudável","🟡 Atenção"))), IF(AND($B28="Ativo",$C28="Faturamento inativo"),"🔴 Risco",IF($C28="","⚪ Sem dados","🟡 Atenção")))) -> 🟡 Atenção | F28: 08.183.084/0001-58 | G28: Kener | H28: (31) 99484-0038 | I28: kener.silva@pwtransporte.com.br | J28: 45997 | K28: =COUNTIFS('Módulos'!$G$2:$G$2464,A28,'Módulos'!$I$2:$I$2464,"ATIVO") -> 205 | L28: Módulos operando | M28: Planilha | N28: Telemetria II | O28: Fidelizar | P28: Capacitação em Desenvolvimento | Q28: Em POC | R28: 46218
A29: PLENA | B29: Proposta comercial | C29: Faturamento inativo | D29: Guilherme | E29: =IF(OR($B29="POC Sem Evolução",$B29="Prospecção Sem Sucesso",$B29="Inativo",$B29="Prospecção"), "⚪ Sem dados",IF($C29="Faturando",IF($Q29="Com evolução","🟢 Saudável",IF($Q29="Sem evolução", "🟡 Atenção",IF(AND($P29="Capacitação Efetiva",$L29="Módulos operando"),"🟢 Saudável","🟡 Atenção"))), IF(AND($B29="Ativo",$C29="Faturamento inativo"),"🔴 Risco",IF($C29="","⚪ Sem dados","🟡 Atenção")))) -> 🟡 Atenção | F29: 42.722.360/0004-90 | G29: Bruno | H29: (32) 99912-5086 | I29: bruno.nascimento@grupomysa.com.br | J29: 46075 | K29: =COUNTIFS('Módulos'!$G$2:$G$2464,A29,'Módulos'!$I$2:$I$2464,"ATIVO") -> 6 | L29: Módulos operando | M29: Sascar | N29: Telemetria II | O29: Fidelizar | P29: Realizar Capacitação | Q29: Em POC | R29: 46210
A30: PORTINARI | B30: Inativo | C30: Faturamento inativo | D30: Guilherme | E30: =IF(OR($B30="POC Sem Evolução",$B30="Prospecção Sem Sucesso",$B30="Inativo",$B30="Prospecção"), "⚪ Sem dados",IF($C30="Faturando",IF($Q30="Com evolução","🟢 Saudável",IF($Q30="Sem evolução", "🟡 Atenção",IF(AND($P30="Capacitação Efetiva",$L30="Módulos operando"),"🟢 Saudável","🟡 Atenção"))), IF(AND($B30="Ativo",$C30="Faturamento inativo"),"🔴 Risco",IF($C30="","⚪ Sem dados","🟡 Atenção")))) -> ⚪ Sem dados | F30: 06.871.927/0001-83 | G30: Warlen | H30: (31) 99942-4685 | I30: comercial@portinaritransportes.com.br | J30: 45955 | K30: =COUNTIFS('Módulos'!$G$2:$G$2464,A30,'Módulos'!$I$2:$I$2464,"ATIVO") -> 7 | L30: Módulos operando | M30: Inoprime | N30: Telemetria II | O30: Fidelidade 12 meses | P30: Inativado | Q30: Inativado | R30: 46216
A31: R&M | B31: Ativo | C31: Faturando | D31: Diego | E31: =IF(OR($B31="POC Sem Evolução",$B31="Prospecção Sem Sucesso",$B31="Inativo",$B31="Prospecção"), "⚪ Sem dados",IF($C31="Faturando",IF($Q31="Com evolução","🟢 Saudável",IF($Q31="Sem evolução", "🟡 Atenção",IF(AND($P31="Capacitação Efetiva",$L31="Módulos operando"),"🟢 Saudável","🟡 Atenção"))), IF(AND($B31="Ativo",$C31="Faturamento inativo"),"🔴 Risco",IF($C31="","⚪ Sem dados","🟡 Atenção")))) -> 🟢 Saudável | F31: 42.883.904/0001-52 | G31: Rafael | H31: (31) 99961-1008 | I31: rafael.morais@lenarge.com.br | J31: 45901 | K31: =COUNTIFS('Módulos'!$G$2:$G$2464,A31,'Módulos'!$I$2:$I$2464,"ATIVO") -> 4 | L31: Módulos operando | M31: Sem dados | N31: Telemetria II | O31: Fidelidade 12 meses | P31: Capacitação Efetiva | Q31: Com evolução
A32: RLR | B32: Ativo | C32: Faturando | D32: Guilherme | E32: =IF(OR($B32="POC Sem Evolução",$B32="Prospecção Sem Sucesso",$B32="Inativo",$B32="Prospecção"), "⚪ Sem dados",IF($C32="Faturando",IF($Q32="Com evolução","🟢 Saudável",IF($Q32="Sem evolução", "🟡 Atenção",IF(AND($P32="Capacitação Efetiva",$L32="Módulos operando"),"🟢 Saudável","🟡 Atenção"))), IF(AND($B32="Ativo",$C32="Faturamento inativo"),"🔴 Risco",IF($C32="","⚪ Sem dados","🟡 Atenção")))) -> 🟢 Saudável | F32: 08.191.899/0001-89 | G32: Laura | H32: (31)97223-1004 | I32: fiscal@rlrtransporte.com.br | J32: 45809 | K32: =COUNTIFS('Módulos'!$G$2:$G$2464,A32,'Módulos'!$I$2:$I$2464,"ATIVO") -> 80 | L32: Módulos operando | M32: Sem dados | N32: Telemetria I | O32: Sem fidelidade | P32: Capacitação Efetiva | Q32: Com evolução
A33: RODEIRO | B33: Inativo | C33: Faturamento inativo | D33: Guilherme | E33: =IF(OR($B33="POC Sem Evolução",$B33="Prospecção Sem Sucesso",$B33="Inativo",$B33="Prospecção"), "⚪ Sem dados",IF($C33="Faturando",IF($Q33="Com evolução","🟢 Saudável",IF($Q33="Sem evolução", "🟡 Atenção",IF(AND($P33="Capacitação Efetiva",$L33="Módulos operando"),"🟢 Saudável","🟡 Atenção"))), IF(AND($B33="Ativo",$C33="Faturamento inativo"),"🔴 Risco",IF($C33="","⚪ Sem dados","🟡 Atenção")))) -> ⚪ Sem dados | F33: - | G33: - | H33: - | I33: - | K33: =COUNTIFS('Módulos'!$G$2:$G$2464,A33,'Módulos'!$I$2:$I$2464,"ATIVO") -> 0 | L33: Telemetria suspensa | M33: Sem dados | N33: Sem acesso | O33: Sem fidelidade | P33: Inativado | Q33: Inativado
A34: SATEL | B34: Prospecção sem Sucesso | C34: Faturamento inativo | D34: Guilherme | E34: =IF(OR($B34="POC Sem Evolução",$B34="Prospecção Sem Sucesso",$B34="Inativo",$B34="Prospecção"), "⚪ Sem dados",IF($C34="Faturando",IF($Q34="Com evolução","🟢 Saudável",IF($Q34="Sem evolução", "🟡 Atenção",IF(AND($P34="Capacitação Efetiva",$L34="Módulos operando"),"🟢 Saudável","🟡 Atenção"))), IF(AND($B34="Ativo",$C34="Faturamento inativo"),"🔴 Risco",IF($C34="","⚪ Sem dados","🟡 Atenção")))) -> ⚪ Sem dados | F34: - | G34: - | H34: - | I34: - | K34: =COUNTIFS('Módulos'!$G$2:$G$2464,A34,'Módulos'!$I$2:$I$2464,"ATIVO") -> 0 | L34: Telemetria suspensa | M34: Sem dados | N34: Sem acesso | O34: Fidelizar | P34: Inativado | Q34: Inativado
A35: SEMPRE VOLTA | B35: Ativo | C35: Faturando | D35: Diego | E35: =IF(OR($B35="POC Sem Evolução",$B35="Prospecção Sem Sucesso",$B35="Inativo",$B35="Prospecção"), "⚪ Sem dados",IF($C35="Faturando",IF($Q35="Com evolução","🟢 Saudável",IF($Q35="Sem evolução", "🟡 Atenção",IF(AND($P35="Capacitação Efetiva",$L35="Módulos operando"),"🟢 Saudável","🟡 Atenção"))), IF(AND($B35="Ativo",$C35="Faturamento inativo"),"🔴 Risco",IF($C35="","⚪ Sem dados","🟡 Atenção")))) -> 🟢 Saudável | F35: 20.786.711/0001-40 | G35: Brenda | H35: (31) 99898-1729 | I35: qualidade@semprevolta.net.br | J35: 46103 | K35: =COUNTIFS('Módulos'!$G$2:$G$2464,A35,'Módulos'!$I$2:$I$2464,"ATIVO") -> 33 | L35: Módulos operando | M35: Diário de Bordo | N35: Telemetria II | O35: Fidelidade 12 meses | P35: Capacitação Efetiva | Q35: Com evolução | R35: 46223
A36: TRANSFAL | B36: Prospecção sem Sucesso | C36: Faturamento inativo | E36: =IF(OR($B36="POC Sem Evolução",$B36="Prospecção Sem Sucesso",$B36="Inativo",$B36="Prospecção"), "⚪ Sem dados",IF($C36="Faturando",IF($Q36="Com evolução","🟢 Saudável",IF($Q36="Sem evolução", "🟡 Atenção",IF(AND($P36="Capacitação Efetiva",$L36="Módulos operando"),"🟢 Saudável","🟡 Atenção"))), IF(AND($B36="Ativo",$C36="Faturamento inativo"),"🔴 Risco",IF($C36="","⚪ Sem dados","🟡 Atenção")))) -> ⚪ Sem dados | K36: =COUNTIFS('Módulos'!$G$2:$G$2464,A36,'Módulos'!$I$2:$I$2464,"ATIVO") -> 0 | L36: Telemetria suspensa | M36: Sem dados | N36: Sem acesso | O36: Fidelizar | P36: Inativado | Q36: Inativado
A37: TRANSNIEL | B37: Prospecção | C37: Faturamento inativo | D37: Guilherme | E37: =IF(OR($B37="POC Sem Evolução",$B37="Prospecção Sem Sucesso",$B37="Inativo",$B37="Prospecção"), "⚪ Sem dados",IF($C37="Faturando",IF($Q37="Com evolução","🟢 Saudável",IF($Q37="Sem evolução", "🟡 Atenção",IF(AND($P37="Capacitação Efetiva",$L37="Módulos operando"),"🟢 Saudável","🟡 Atenção"))), IF(AND($B37="Ativo",$C37="Faturamento inativo"),"🔴 Risco",IF($C37="","⚪ Sem dados","🟡 Atenção")))) -> ⚪ Sem dados | F37: - | G37: - | H37: - | I37: - | K37: =COUNTIFS('Módulos'!$G$2:$G$2464,A37,'Módulos'!$I$2:$I$2464,"ATIVO") -> 0 | L37: Checar módulos | M37: Sem dados | N37: Sem acesso | O37: Sem fidelidade | P37: Realizar Capacitação | Q37: Sem dados | R37: 46217
A38: TRANSPORTADORA IRMÃOS GOMES | B38: Prospecção | C38: Faturamento inativo | D38: Diego | E38: =IF(OR($B38="POC Sem Evolução",$B38="Prospecção Sem Sucesso",$B38="Inativo",$B38="Prospecção"), "⚪ Sem dados",IF($C38="Faturando",IF($Q38="Com evolução","🟢 Saudável",IF($Q38="Sem evolução", "🟡 Atenção",IF(AND($P38="Capacitação Efetiva",$L38="Módulos operando"),"🟢 Saudável","🟡 Atenção"))), IF(AND($B38="Ativo",$C38="Faturamento inativo"),"🔴 Risco",IF($C38="","⚪ Sem dados","🟡 Atenção")))) -> ⚪ Sem dados | F38: - | G38: - | H38: - | I38: - | K38: =COUNTIFS('Módulos'!$G$2:$G$2464,A38,'Módulos'!$I$2:$I$2464,"ATIVO") -> 0 | L38: Checar módulos | M38: Sem dados | N38: Sem acesso | O38: Sem fidelidade | P38: Realizar Capacitação | Q38: Sem dados
A39: TRANSPORTADORA NOVA ERA | B39: POC Sem Evolução | C39: Faturamento inativo | D39: Diego | E39: =IF(OR($B39="POC Sem Evolução",$B39="Prospecção Sem Sucesso",$B39="Inativo",$B39="Prospecção"), "⚪ Sem dados",IF($C39="Faturando",IF($Q39="Com evolução","🟢 Saudável",IF($Q39="Sem evolução", "🟡 Atenção",IF(AND($P39="Capacitação Efetiva",$L39="Módulos operando"),"🟢 Saudável","🟡 Atenção"))), IF(AND($B39="Ativo",$C39="Faturamento inativo"),"🔴 Risco",IF($C39="","⚪ Sem dados","🟡 Atenção")))) -> ⚪ Sem dados | F39: 00.103.768/0001-90 | G39: Afranio | H39: (31) 99492-0164 | I39: afraniocaetano@transportesnovaera.com.br | J39: 46162 | K39: =COUNTIFS('Módulos'!$G$2:$G$2464,A39,'Módulos'!$I$2:$I$2464,"ATIVO") -> 0 | L39: Telemetria suspensa | M39: Maxtrack | N39: Sem acesso | O39: Fidelizar | P39: Inativado | Q39: Inativado
A40: TRANSKOMPA | B40: POC Sem Evolução | C40: Faturamento inativo | D40: Guilherme | E40: =IF(OR($B40="POC Sem Evolução",$B40="Prospecção Sem Sucesso",$B40="Inativo",$B40="Prospecção"), "⚪ Sem dados",IF($C40="Faturando",IF($Q40="Com evolução","🟢 Saudável",IF($Q40="Sem evolução", "🟡 Atenção",IF(AND($P40="Capacitação Efetiva",$L40="Módulos operando"),"🟢 Saudável","🟡 Atenção"))), IF(AND($B40="Ativo",$C40="Faturamento inativo"),"🔴 Risco",IF($C40="","⚪ Sem dados","🟡 Atenção")))) -> ⚪ Sem dados | F40: 65.311.235/0001-40 | G40: Adelson | H40: (11) 96377-7218 | I40: adelson.sena@transkompa.com.br | J40: 45901 | K40: =COUNTIFS('Módulos'!$G$2:$G$2464,A40,'Módulos'!$I$2:$I$2464,"ATIVO") -> 13 | L40: Módulos operando | M40: Boreal | N40: Sem acesso | O40: Fidelizar | P40: Inativado | Q40: Inativado | R40: 46219
...

Sheet Pipeline
A1: Prioridade | B1: Empresa | C1: Segmento | D1: UF/Região | E1: Nº veíc. (est.) | F1: Decisor-alvo | G1: Canal | H1: Estágio | I1: Próxima ação | J1: Data próx. ação | K1: Valor ponderado | L1: Dor / Gancho | M1: Observações
A2: A | B2: Expresso Alvorada | C2: Granel sólido (cimento/siderurgia/coque) | D2: MG | F2: Diretor de Operações / Dono | G2: Indicação | H2: Lead | I2: Diagnóstico de risco Lei 13.103 | K2: {=IFERROR($E2*Config!$P$2*INDEX(Config!$K$3:$K$10,MATCH($H2,Config!$J$3:$J$10,0)),0)} -> 0 | L2: Espelho da Aperam; já usa rastreamento satelital
A3: A | B3: GT Minas Transportes | C3: Granel / container | D3: Varginha-MG | F3: Gestor de Frota | G3: Outbound LinkedIn | H3: Lead | I3: Enviar diagnóstico gratuito | K3: {=IFERROR($E3*Config!$P$2*INDEX(Config!$K$3:$K$10,MATCH($H3,Config!$J$3:$J$10,0)),0)} -> 0 | L3: Frota 100% rastreada, mid-market MG
A4: A | B4: Transportes Faraem | C4: Graneleiro (Sul/Sudeste) | D4: RS/SC | F4: Diretor de Operações | G4: Outbound e-mail | H4: Lead | I4: Calculadora ROI diesel | K4: {=IFERROR($E4*Config!$P$2*INDEX(Config!$K$3:$K$10,MATCH($H4,Config!$J$3:$J$10,0)),0)} -> 0 | L4: Graneleiro longa distância
A5: A | B5: Sada Transportes | C5: Cegonha / siderurgia | D5: Betim-MG | F5: Diretor de Operações | G5: Indicação | H5: Lead | I5: Case Aperam mesma região | K5: {=IFERROR($E5*Config!$P$2*INDEX(Config!$K$3:$K$10,MATCH($H5,Config!$J$3:$J$10,0)),0)} -> 0 | L5: Peer siderúrgico da Aperam
A6: A | B6: Transpanorama | C6: Granel líquido / químico | D6: RS | F6: COO | G6: Outbound LinkedIn | H6: Lead | I6: Diagnóstico de jornada (carga perigosa) | K6: {=IFERROR($E6*Config!$P$2*INDEX(Config!$K$3:$K$10,MATCH($H6,Config!$J$3:$J$10,0)),0)} -> 0 | L6: Longa distância + carga perigosa
A7: A | B7: Expresso Nepomuceno | C7: Carga geral longa distância | D7: Três Corações-MG | F7: Diretor / Dono | G7: Indicação | H7: Lead | I7: Pedir indicação via cliente MG | K7: {=IFERROR($E7*Config!$P$2*INDEX(Config!$K$3:$K$10,MATCH($H7,Config!$J$3:$J$10,0)),0)} -> 0 | L7: Tradicional MG, frota própria
A8: A | B8: Del Rey Transportes | C8: Carga geral | D8: BH-MG | F8: Dono / Diretor | G8: Outbound LinkedIn | H8: Lead | I8: One-pager compliance + demo | K8: {=IFERROR($E8*Config!$P$2*INDEX(Config!$K$3:$K$10,MATCH($H8,Config!$J$3:$J$10,0)),0)} -> 0 | L8: Mid-market MG
A9: A | B9: Transmathias Transportes | C9: Carga / granel | D9: MG | F9: Dono / Gestor de Frota | G9: Indicação | H9: Lead | I9: Diagnóstico + indicação regional | K9: {=IFERROR($E9*Config!$P$2*INDEX(Config!$K$3:$K$10,MATCH($H9,Config!$J$3:$J$10,0)),0)} -> 0 | L9: Mid-market MG
A10: A | B10: Tora Transportes | C10: Granel sólido longa distância | D10: Nacional | F10: Diretor de Operações | G10: Outbound e-mail | H10: Lead | I10: ROI por veículo | K10: {=IFERROR($E10*Config!$P$2*INDEX(Config!$K$3:$K$10,MATCH($H10,Config!$J$3:$J$10,0)),0)} -> 0 | L10: Alto consumo diesel
A11: A | B11: Rodovale / Rodocap | C11: Granel / carga | D11: MG / interior | F11: Gestor de Frota | G11: Outbound LinkedIn | H11: Lead | I11: Calculadora de ROI | K11: {=IFERROR($E11*Config!$P$2*INDEX(Config!$K$3:$K$10,MATCH($H11,Config!$J$3:$J$10,0)),0)} -> 0 | L11: Graneleiro mid-market
A12: B | B12: Cooxupé | C12: Cooperativa de café | D12: Guaxupé-MG/SP | F12: Diretor de Logística | G12: Evento | H12: Lead | I12: Assessment de safra + case MG | K12: {=IFERROR($E12*Config!$P$2*INDEX(Config!$K$3:$K$10,MATCH($H12,Config!$J$3:$J$10,0)),0)} -> 0 | L12: Coop MG (quintal), pico de safra
A13: B | B13: Coamo | C13: Cooperativa agro (grãos) | D13: Campo Mourão-PR | F13: Diretor de Logística | G13: Evento | H13: Lead | I13: Assessment safra + case Coopervale | K13: {=IFERROR($E13*Config!$P$2*INDEX(Config!$K$3:$K$10,MATCH($H13,Config!$J$3:$J$10,0)),0)} -> 0 | L13: Frota própria grande
... A25: C | B25: JBS / Marfrig / Aurora | C25: Frigorífico / proteína | D25: Nacional / Sul | F25: Gerente de Logística regional | G25: Indicação | H25: Lead | I25: Dor de perecível parado | K25: {=IFERROR($E25*Config!$P$2*INDEX(Config!$K$3:$K$10,MATCH($H25,Config!$J$3:$J$10,0)),0)} -> 0 | L25: Frota frigorificada própria

Sheet Controle de OS
A1: Nº DA OS | B1: STATUS | C1: QUEM ABRIU | D1: EMPRESA | E1: SOLICITANTE | F1: CONTATO | G1: DATA | H1: HORA | I1: CRITICIDADE | J1: ANALISTA | K1: PRODUTO/SERVIÇO | L1: DESCRIÇÃO DA DEMANDA | M1: PLACA | N1: SLA (Objetivo) | O1: VENCIMENTO | P1: SOLUÇÃO/COMENTÁRIOS/EVOLUÇÃO | Q1: CONCLUSÃO
A2: 2026000001 | B2: FINALIZADO | C2: MARLON | D2: M1 | E2: Deivson Figueredo | G2: 46027 | H2: 0 | I2: ATENDIDO | J2: MARLON | K2: SUPORTE | L2: Relatório de rastreio | M2: TCR3G73 | N2: 46027 | O2: =IF(N2="","SEM DATA APONTADA",(IF(B2="FINALIZADO", "CONCLUÍDO",(IF(B2="ANALISADO", "ANALISADO",IF(N2<TODAY(), "VENCIDO", IF(N2=TODAY(), "VENCE HOJE", IF(N2<=TODAY()+5,"VENCENDO", "NO PRAZO")))))))) -> CONCLUÍDO | P2: Enviei o relatorio | Q2: 46027
A3: 2026000002 | B3: FINALIZADO | C3: MARLON | D3: LENARGE | E3: Gabriel Felipe Viana da Silva | G3: 46027 | H3: 0 | I3: ATENDIDO | J3: MARLON | K3: SUPORTE | L3: Disponibilizar acesso ao APP LENARGE | N3: 46027 | O3: =IF(N3="","SEM DATA APONTADA",(IF(B3="FINALIZADO", "CONCLUÍDO",(IF(B3="ANALISADO", "ANALISADO",IF(N3<TODAY(), "VENCIDO", IF(N3=TODAY(), "VENCE HOJE", IF(N3<=TODAY()+5,"VENCENDO", "NO PRAZO")))))))) -> CONCLUÍDO | P3: Acesso ao APP Lenarge concedido. | Q3: 46027
A4: 2026000003 | B4: FINALIZADO | C4: MARLON | D4: LENARGE | E4: Gabriel Fernandes inacio | G4: 46027 | H4: 0 | I4: ATENDIDO | J4: MARLON | K4: SUPORTE | L4: Lentidão generalizada no App Lenarge | N4: 46027 | O4: =IF(N4="","SEM DATA APONTADA",(IF(B4="FINALIZADO", "CONCLUÍDO",(IF(B4="ANALISADO", "ANALISADO",IF(N4<TODAY(), "VENCIDO", IF(N4=TODAY(), "VENCE HOJE", IF(N4<=TODAY()+5,"VENCENDO", "NO PRAZO")))))))) -> CONCLUÍDO | Q4: =N4 -> 46027
A5: 2026000004 | B5: FINALIZADO | C5: MARLON | D5: DNA | E5: Deivson Figueredo | G5: 46027 | H5: 0 | I5: ATENDIDO | J5: MARLON | K5: TELEMETRIA | L5: Veiculos não estão reportando no tracking | M5: QUX9C89 | N5: 46028 | O5: =IF(N5="","SEM DATA APONTADA",(IF(B5="FINALIZADO", "CONCLUÍDO",(IF(B5="ANALISADO", "ANALISADO",IF(N5<TODAY(), "VENCIDO", IF(N5=TODAY(), "VENCE HOJE", IF(N5<=TODAY()+5,"VENCENDO", "NO PRAZO")))))))) -> CONCLUÍDO | P5: Enviei a config | Q5: 46028
B6: FINALIZADO | D6: DNA | H6: 0 | I6: ATENDIDO | J6: MARLON | K6: TELEMETRIA | M6: QOL5H74 | N6: 46028 | O6: =IF(N6="","SEM DATA APONTADA",(IF(B6="FINALIZADO", "CONCLUÍDO",(IF(B6="ANALISADO", "ANALISADO",IF(N6<TODAY(), "VENCIDO", IF(N6=TODAY(), "VENCE HOJE", IF(N6<=TODAY()+5,"VENCENDO", "NO PRAZO")))))))) -> CONCLUÍDO | P6: Enviei a config | Q6: 46028
B7: FINALIZADO | D7: DNA | H7: 0 | I7: ATENDIDO | J7: MARLON | K7: TELEMETRIA | M7: QPQ2J79 | N7: 46028 | O7: =IF(N7="","SEM DATA APONTADA",(IF(B7="FINALIZADO", "CONCLUÍDO",(IF(B7="ANALISADO", "ANALISADO",IF(N7<TODAY(), "VENCIDO", IF(N7=TODAY(), "VENCE HOJE", IF(N7<=TODAY()+5,"VENCENDO", "NO PRAZO")))))))) -> CONCLUÍDO | P7: Enviei a config | Q7: 46028
B8: FINALIZADO | D8: DNA | H8: 0 | I8: ATENDIDO | J8: MARLON | K8: TELEMETRIA | M8: QMT4G46 | N8: 46028 | O8: =IF(N8="","SEM DATA APONTADA",(IF(B8="FINALIZADO", "CONCLUÍDO",(IF(B8="ANALISADO", "ANALISADO",IF(N8<TODAY(), "VENCIDO", IF(N8=TODAY(), "VENCE HOJE", IF(N8<=TODAY()+5,"VENCENDO", "NO PRAZO")))))))) -> CONCLUÍDO | P8: Enviei a config | Q8: 46028
B9: FINALIZADO | D9: DNA | H9: 0 | I9: ATENDIDO | J9: MARLON | K9: TELEMETRIA | M9: RNU5H15 | N9: 46028 | O9: =IF(N9="","SEM DATA APONTADA",(IF(B9="FINALIZADO", "CONCLUÍDO",(IF(B9="ANALISADO", "ANALISADO",IF(N9<TODAY(), "VENCIDO", IF(N9=TODAY(), "VENCE HOJE", IF(N9<=TODAY()+5,"VENCENDO", "NO PRAZO")))))))) -> CONCLUÍDO | P9: Enviei a config | Q9: 46028
A10: 2026000005 | B10: FINALIZADO | C10: MARLON | D10: LENARGE | E10: Maria Vieira | G10: 46027 | H10: 0 | I10: ATENDIDO | J10: PABLO | K10: TORRE | L10: Disponibilizar acesso ao APP LENARGE e liberação de permissão a funcionalidade de troca de motorista | N10: 46027 | O10: =IF(N10="","SEM DATA APONTADA",(IF(B10="FINALIZADO", "CONCLUÍDO",(IF(B10="ANALISADO", "ANALISADO",IF(N10<TODAY(), "VENCIDO", IF(N10=TODAY(), "VENCE HOJE", IF(N10<=TODAY()+5,"VENCENDO", "NO PRAZO")))))))) -> CONCLUÍDO | P10: Acesso ao APP Lenarge concedido e permissão para troca de motorista liberada. | Q10: 46027
A11: 2026000006 | B11: FINALIZADO | C11: MARLON | D11: LENARGE | E11: Letícia Cristina | G11: 46027 | H11: 0 | I11: ATENDIDO | J11: MARLON | K11: SUPORTE | L11: Falha freios / Falha elétrica / Perda de funcionalidade / Tacógrafo com defeito / Funcionalidade transmissão reduzida. | M11: RBE9D16 | N11: 46027 | O11: =IF(N11="","SEM DATA APONTADA",(IF(B11="FINALIZADO", "CONCLUÍDO",(IF(B11="ANALISADO", "ANALISADO",IF(N11<TODAY(), "VENCIDO", IF(N11=TODAY(), "VENCE HOJE", IF(N11<=TODAY()+5,"VENCENDO", "NO PRAZO")))))))) -> CONCLUÍDO | P11: Enviei a config | Q11: 46027
A12: 2026000007 | B12: FINALIZADO | C12: MARLON | D12: LENARGE | E12: Vinicius Moraes | G12: 46025 | H12: 0 | I12: ATENDIDO | J12: PABLO | K12: TORRE | L12: Autorização de perimissão a trocca de motorista | N12: 46027 | O12: =IF(N12="","SEM DATA APONTADA",(IF(B12="FINALIZADO", "CONCLUÍDO",(IF(B12="ANALISADO", "ANALISADO",IF(N12<TODAY(), "VENCIDO", IF(N12=TODAY(), "VENCE HOJE", IF(N12<=TODAY()+5,"VENCENDO", "NO PRAZO")))))))) -> CONCLUÍDO | P12: Permissão liberada apos aurotização do setor de faturamento (Juliana) | Q12: 46027
A13: 2026000008 | B13: FINALIZADO | C13: MARLON | D13: LENARGE | E13: João Machado | G13: 46027 | H13: 0 | I13: ATENDIDO | J13: PABLO | K13: TORRE | L13: Disponibilizar acesso ao APP LENARGE e liberação de permissão a funcionalidade de troca de motorista | N13: 46027 | O13: =IF(N13="","SEM DATA APONTADA",(IF(B13="FINALIZADO", "CONCLUÍDO",(IF(B13="ANALISADO", "ANALISADO",IF(N13<TODAY(), "VENCIDO", IF(N13=TODAY(), "VENCE HOJE", IF(N13<=TODAY()+5,"VENCENDO", "NO PRAZO")))))))) -> CONCLUÍDO | P13: Acesso ao APP Lenarge concedido e permissão para troca de motorista liberada. | Q13: 46027
A14: 2026000009 | B14: FINALIZADO | C14: MARLON | D14: M1 | E14: Deivson Figueredo | G14: 46027 | H14: 0 | I14: ATENDIDO | J14: MARLON | K14: SUPORTE | L14: Auxilio para emitir relatório de premiação | N14: 46027 | O14: =IF(N14="","SEM DATA APONTADA",(IF(B14="FINALIZADO", "CONCLUÍDO",(IF(B14="ANALISADO", "ANALISADO",IF(N14<TODAY(), "VENCIDO", IF(N14=TODAY(), "VENCE HOJE", IF(N14<=TODAY()+5,"VENCENDO", "NO PRAZO")))))))) -> CONCLUÍDO | P14: Usuário orientado quanto ao procedimento correto para emissão do relatório de premiação no sistema, com sucesso. | Q14: 46027
A15: 2026000010 | B15: FINALIZADO | C15: MARLON | D15: LENARGE | E15: João Machado | G15: 46027 | H15: 0 | I15: ATENDIDO | J15: MARLON | K15: SUPORTE | L15: Atualizar app Betruck no Knox | N15: 46027 | O15: =IF(N15="","SEM DATA APONTADA",(IF(B15="FINALIZADO", "CONCLUÍDO",(IF(B15="ANALISADO", "ANALISADO",IF(N15<TODAY(), "VENCIDO", IF(N15=TODAY(), "VENCE HOJE", IF(N15<=TODAY()+5,"VENCENDO", "NO PRAZO")))))))) -> CONCLUÍDO | P15: App foi atualizado | Q15: 46027
A16: 2026000011 | B16: FINALIZADO | C16: MARLON | D16: LENARGE | E16: Letícia Cristina | G16: 46027 | H16: 0 | I16: ATENDIDO | J16: MARLON | K16: SUPORTE | L16: Não está mostrando os comandos para o motorista | M16: RBE5G92 | N16: 46027 | O16: =IF(N16="","SEM DATA APONTADA",(IF(B16="FINALIZADO", "CONCLUÍDO",(IF(B16="ANALISADO", "ANALISADO",IF(N16<TODAY(), "VENCIDO", IF(N16=TODAY(), "VENCE HOJE", IF(N16<=TODAY()+5,"VENCENDO", "NO PRAZO")))))))) -> CONCLUÍDO | P16: Enviei a config | Q16: 46027
A17: 2026000012 | B17: FINALIZADO | C17: DIEGO | D17: FACSS | E17: Diego Sena | G17: 46027 | H17: 0 | I17: ATENDIDO | J17: MARLON | K17: SUPORTE | L17: Veiculos não estão reportando no tracking, Traccar e Dashboard | N17: 46031 | O17: =IF(N17="","SEM DATA APONTADA",(IF(B17="FINALIZADO", "CONCLUÍDO",(IF(B17="ANALISADO", "ANALISADO",IF(N17<TODAY(), "VENCIDO", IF(N17=TODAY(), "VENCE HOJE", IF(N17<=TODAY()+5,"VENCENDO", "NO PRAZO")))))))) -> CONCLUÍDO | P17: Solicitada a troca dos módulos, pois o reenvio da config não foi aplicado com sucesso e os veículos não voltaram a reportar. | Q17: 46028
A18: 2026000013 | B18: FINALIZADO | C18: MARLON | D18: FACSS | E18: Leonardo Branco | G18: 46027 | H18: 0 | I18: ATENDIDO | J18: MARLON | K18: SUPORTE | L18: Criar usuario para P&W | N18: 46027 | O18: =IF(N18="","SEM DATA APONTADA",(IF(B18="FINALIZADO", "CONCLUÍDO",(IF(B18="ANALISADO", "ANALISADO",IF(N18<TODAY(), "VENCIDO", IF(N18=TODAY(), "VENCE HOJE", IF(N18<=TODAY()+5,"VENCENDO", "NO PRAZO")))))))) -> CONCLUÍDO | P18: Usuario criado com sucesso. | Q18: 46027
A19: 2026000014 | B19: FINALIZADO | C19: MARLON | D19: LENARGE | E19: Walker Rodrigues | G19: 46028 | H19: 0 | I19: ATENDIDO | J19: PABLO | K19: TORRE | L19: Rastreador não funciona no app Lenarge. | N19: 46028 | O19: =IF(N19="","SEM DATA APONTADA",(IF(B19="FINALIZADO", "CONCLUÍDO",(IF(B19="ANALISADO", "ANALISADO",IF(N19<TODAY(), "VENCIDO", IF(N19=TODAY(), "VENCE HOJE", IF(N19<=TODAY()+5,"VENCENDO", "NO PRAZO")))))))) -> CONCLUÍDO | P19: Por falta de retorno do solicitante o chamado foiu encerrado. | Q19: 46028
A20: 2026000015 | B20: FINALIZADO | C20: DIEGO | D20: LENARGE | E20: Leandro Galdino | G20: 46028 | H20: 0 | I20: ATENDIDO | J20: DIEGO | K20: TELEMETRIA | L20: Veiculo não apresenta dados de telemetria | M20: RFZ4I84 | N20: 46028 | O20: =IF(N20="","SEM DATA APONTADA",(IF(B20="FINALIZADO", "CONCLUÍDO",(IF(B20="ANALISADO", "ANALISADO",IF(N20<TODAY(), "VENCIDO", IF(N20=TODAY(), "VENCE HOJE", IF(N20<=TODAY()+5,"VENCENDO", "NO PRAZO")))))))) -> CONCLUÍDO | P20: Será realizada a troca do módulo | Q20: 46028
A21: 2026000016 | B21: FINALIZADO | C21: MARLON | D21: APERAM Carvão | E21: Fernando Aristeu | G21: 46028 | H21: 0 | I21: ATENDIDO | J21: DIEGO | K21: SUPORTE | L21: Relatório completo de quilômetros rodados no mês de dezembro, bem como a quantidade de combustível consumida, discriminado por frota. | N21: 46028 | O21: =IF(N21="","SEM DATA APONTADA",(IF(B21="FINALIZADO", "CONCLUÍDO",(IF(B21="ANALISADO", "ANALISADO",IF(N21<TODAY(), "VENCIDO", IF(N21=TODAY(), "VENCE HOJE", IF(N21<=TODAY()+5,"VENCENDO", "NO PRAZO")))))))) -> CONCLUÍDO | P21: Relatório enviado. | Q21: 46028
A22: 2026000017 | B22: FINALIZADO | C22: MARLON | D22: LENARGE | E22: Leandro Galdino | G22: 46028 | H22: 0 | I22: ATENDIDO | J22: PABLO | K22: TORRE | L22: Veículo apresenta dados de telemetria apenas vinculados à placa e não ao motorista, impedindo que o motorista visualize suas informações de condução. | M22: RKR7J21 | N22: 46030 | O22: =IF(N22="","SEM DATA APONTADA",(IF(B22="FINALIZADO", "CONCLUÍDO",(IF(B22="ANALISADO", "ANALISADO",IF(N22<TODAY(), "VENCIDO", IF(N22=TODAY(), "VENCE HOJE", IF(N22<=TODAY()+5,"VENCENDO", "NO PRAZO")))))))) -> CONCLUÍDO | P22: Veículo identificado em manutenção, sem transmissão de sinal desde 09/01 às 18:06. Última localização registrada na concessionária DAF, indicando possível desligamento durante o processo de manutenção. Performance do motorista encontra-se normal. Possível falha ou desligamento do rastreador durante a manutenção. | Q22: 46037
A23: 2026000018 | B23: FINALIZADO | C23: MARLON | D23: LENARGE | E23: Amanda | G23: 46028 | H23: 0 | I23: ATENDIDO | J23: MARLON | K23: SUPORTE | L23: Criar usuario para funcionário do controle de manutenção | N23: 46028 | O23: =IF(N23="","SEM DATA APONTADA",(IF(B23="FINALIZADO", "CONCLUÍDO",(IF(B23="ANALISADO", "ANALISADO",IF(N23<TODAY(), "VENCIDO", IF(N23=TODAY(), "VENCE HOJE", IF(N23<=TODAY()+5,"VENCENDO", "NO PRAZO")))))))) -> CONCLUÍDO | P23: Usuario criado com sucesso. | Q23: 46028
A24: 2026000020 | B24: FINALIZADO | C24: DIEGO | D24: FACSS | E24: Diego Sena | G24: 46028 | H24: 0 | I24: ATENDIDO | J24: MARLON | K24: SUPORTE | L24: Veiculos não estão reportando no tracking, Traccar e Dashboard | N24: 46030 | O24: =IF(N24="","SEM DATA APONTADA",(IF(B24="FINALIZADO", "CONCLUÍDO",(IF(B24="ANALISADO", "ANALISADO",IF(N24<TODAY(), "VENCIDO", IF(N24=TODAY(), "VENCE HOJE", IF(N24<=TODAY()+5,"VENCENDO", "NO PRAZO")))))))) -> CONCLUÍDO | Q24: 46030
A25: 2026000021 | B25: FINALIZADO | C25: MARLON | D25: LENARGE | E25: Walker Rodrigues | G25: 46028 | H25: 0 | I25: ATENDIDO | J25: MARLON | K25: SUPORTE | L25: Falha no EBS | M25: TTR8H44 | N25: 46028 | O25: =IF(N25="","SEM DATA APONTADA",(IF(B25="FINALIZADO", "CONCLUÍDO",(IF(B25="ANALISADO", "ANALISADO",IF(N25<TODAY(), "VENCIDO", IF(N25=TODAY(), "VENCE HOJE", IF(N25<=TODAY()+5,"VENCENDO", "NO PRAZO")))))))) -> CONCLUÍDO | P25: Enviei a config | Q25: 46028
A26: 2026000022 | B26: FINALIZADO | C26: MARLON | D26: LENARGE | E26: Amanda | G26: 46028 | H26: 0 | I26: ATENDIDO | J26: MARLON | K26: SUPORTE | L26: Criar usuario para funcionário do controle de manutenção | N26: 46028 | O26: =IF(N26="","SEM DATA APONTADA",(IF(B26="FINALIZADO", "CONCLUÍDO",(IF(B26="ANALISADO", "ANALISADO",IF(N26<TODAY(), "VENCIDO", IF(N26=TODAY(), "VENCE HOJE", IF(N26<=TODAY()+5,"VENCENDO", "NO PRAZO")))))))) -> CONCLUÍDO | P26: Usuario criado com sucesso. | Q26: 46028
A27: 2026000023 | B27: FINALIZADO | C27: MARLON | D27: RLR | E27: Alessandro | G27: 45664 | H27: 0 | I27: ATENDIDO | J27: PABLO | K27: TORRE | L27: Veículo apresenta dados de telemetria apenas vinculados à placa e não ao motorista, impedindo que o motorista visualize suas informações de condução. | M27: TCU5I71 | N27: 46030 | O27: =IF(N27="","SEM DATA APONTADA",(IF(B27="FINALIZADO", "CONCLUÍDO",(IF(B27="ANALISADO", "ANALISADO",IF(N27<TODAY(), "VENCIDO", IF(N27=TODAY(), "VENCE HOJE", IF(N27<=TODAY()+5,"VENCENDO", "NO PRAZO")))))))) -> CONCLUÍDO | P27: Houve a troca do ID do motorista, o sistema voltará a reportar normalmente após a atualização realizada. | Q27: =N27 -> 46030
A28: 2026000024 | B28: FINALIZADO | C28: DIEGO | D28: LENARGE | E28: Breno Vinícius | G28: 45664 | H28: 0 | I28: ATENDIDO | J28: GABRIEL | K28: TELEMETRIA | L28: Veiculo não apresenta dados de telemetria | M28: TTR8H42 | N28: 46030 | O28: =IF(N28="","SEM DATA APONTADA",(IF(B28="FINALIZADO", "CONCLUÍDO",(IF(B28="ANALISADO", "ANALISADO",IF(N28<TODAY(), "VENCIDO", IF(N28=TODAY(), "VENCE HOJE", IF(N28<=TODAY()+5,"VENCENDO", "NO PRAZO")))))))) -> CONCLUÍDO | P28: Voltou a reportar no Dashboard. | Q28: 46034
A29: 2026000025 | B29: FINALIZADO | C29: MARLON | D29: LENARGE | E29: Jussara Sacramento | G29: 45664 | H29: 0 | I29: ATENDIDO | J29: PEDRO | K29: SUPORTE | L29: Telefone coorporativo sem internet | N29: 46029 | O29: =IF(N29="","SEM DATA APONTADA",(IF(B29="FINALIZADO", "CONCLUÍDO",(IF(B29="ANALISADO", "ANALISADO",IF(N29<TODAY(), "VENCIDO", IF(N29=TODAY(), "VENCE HOJE", IF(N29<=TODAY()+5,"VENCENDO", "NO PRAZO")))))))) -> CONCLUÍDO | P29: Reiniciado pelo Knox | Q29: 46029
A30: 2026000026 | B30: FINALIZADO | C30: MARLON | D30: LENARGE | E30: Salvador | G30: 46028 | H30: 0 | I30: ATENDIDO | J30: PABLO | K30: TORRE | L30: Veículo apresenta dados de telemetria apenas vinculados à placa e não ao motorista, impedindo que o motorista visualize suas informações de condução. | M30: TTB0J88 | N30: 46029 | O30: =IF(N30="","SEM DATA APONTADA",(IF(B30="FINALIZADO", "CONCLUÍDO",(IF(B30="ANALISADO", "ANALISADO",IF(N30<TODAY(), "VENCIDO", IF(N30=TODAY(), "VENCE HOJE", IF(N30<=TODAY()+5,"VENCENDO", "NO PRAZO")))))))) -> CONCLUÍDO | P30: Houve a troca do rastreador e realizamos a atualização para o ID do rastreador atual no sistema. | Q30: 07/012026
A31: 2026000027 | B31: FINALIZADO | C31: MARLON | D31: LENARGE | E31: Leandro Galdino | G31: 45664 | H31: 0 | I31: ATENDIDO | J31: GABRIEL | K31: TELEMETRIA | L31: Veículo não esta marcando a Inércia de forma correta | M31: SRM3D70 | N31: 46059 | O31: =IF(N31="","SEM DATA APONTADA",(IF(B31="FINALIZADO", "CONCLUÍDO",(IF(B31="ANALISADO", "ANALISADO",IF(N31<TODAY(), "VENCIDO", IF(N31=TODAY(), "VENCE HOJE", IF(N31<=TODAY()+5,"VENCENDO", "NO PRAZO")))))))) -> CONCLUÍDO | P31: A inicia desse veiculo foi resolvida, mas para a resolução ser definitiva é necessario passar essa alterção para o Torre de contole (A alteração feita foi retirar uma das validações que é feita para verificar se o veiculo esta em inecia, retiramos a validação do delta do speed maior que 0), também foi realizada a troca do módulo. | Q31: 46084
A32: 2026000028 | B32: FINALIZADO | C32: MARLON | D32: LENARGE | E32: Mariana Martins | G32: 46029 | H32: 0 | I32: ATENDIDO | J32: PABLO | K32: TORRE | L32: Rastreador da sascar não esta reportando. | M32: TCL9B29 | N32: 46031 | O32: =IF(N32="","SEM DATA APONTADA",(IF(B32="FINALIZADO", "CONCLUÍDO",(IF(B32="ANALISADO", "ANALISADO",IF(N32<TODAY(), "VENCIDO", IF(N32=TODAY(), "VENCE HOJE", IF(N32<=TODAY()+5,"VENCENDO", "NO PRAZO")))))))) -> CONCLUÍDO | P32: Foi diagnosticado que o módulo da sasca estava apresentando falhas. | Q32: 46031
A33: 2026000029 | B33: FINALIZADO | C33: DIEGO | D33: FACSS | E33: Diego Sena | G33: 46029 | H33: 0 | I33: ATENDIDO | J33: MARLON | K33: SUPORTE | L33: Criar usuario para Transportadora Beira Rio | N33: 46029 | O33: =IF(N33="","SEM DATA APONTADA",(IF(B33="FINALIZADO", "CONCLUÍDO",(IF(B33="ANALISADO", "ANALISADO",IF(N33<TODAY(), "VENCIDO", IF(N33=TODAY(), "VENCE HOJE", IF(N33<=TODAY()+5,"VENCENDO", "NO PRAZO")))))))) -> CONCLUÍDO | P33: Usuario criado com sucesso. | Q33: 07/012026
A34: 2026000030 | B34: FINALIZADO | C34: MARLON | D34: LENARGE | E34: Heloiza Carvalho | G34: 45665 | H34: 0 | I34: ATENDIDO | J34: MARLON | K34: SUPORTE | L34: Veículos não estão sendo exibidos no login do vídeo monitoramento FACSS | N34: 45665 | O34: =IF(N34="","SEM DATA APONTADA",(IF(B34="FINALIZADO", "CONCLUÍDO",(IF(B34="ANALISADO", "ANALISADO",IF(N34<TODAY(), "VENCIDO", IF(N34=TODAY(), "VENCE HOJE", IF(N34<=TODAY()+5,"VENCENDO", "NO PRAZO")))))))) -> CONCLUÍDO | P34: Adicionamos as frotas para o usuario do cliente | Q34: 46050
A35: 2026000031 | B35: FINALIZADO | C35: MARLON | D35: LENARGE | E35: Salvador | G35: 45666 | H35: 0 | I35: ATENDIDO | J35: DIEGO | K35: TELEMETRIA | L35: Veiculo não apresenta dados de telemetria | M35: RBE5G92 | N35: 46034 | O35: =IF(N35="","SEM DATA APONTADA",(IF(B35="FINALIZADO", "CONCLUÍDO",(IF(B35="ANALISADO", "ANALISADO",IF(N35<TODAY(), "VENCIDO", IF(N35=TODAY(), "VENCE HOJE", IF(N35<=TODAY()+5,"VENCENDO", "NO PRAZO")))))))) -> CONCLUÍDO | Q35: =N35 -> 46034
A36: 2026000032 | B36: ABERTA | C36: DIEGO | D36: FACSS | E36: Telemetria | G36: 46034 | H36: 0 | I36: MELHORIA/EVOLUÇÃO | J36: NEILOR | K36: P&D | L36: Mercedes Benz não reporta freio motor | N36: 46083 | O36: =IF(N36="","SEM DATA APONTADA",(IF(B36="FINALIZADO", "CONCLUÍDO",(IF(B36="ANALISADO", "ANALISADO",IF(N36<TODAY(), "VENCIDO", IF(N36=TODAY(), "VENCE HOJE", IF(N36<=TODAY()+5,"VENCENDO", "NO PRAZO")))))))) -> VENCIDO
